Workbook

Sheet Documentos
A1: ID | B1: Tipo de literatura | C1: Tipo de documento | D1: Autores | E1: Año | F1: Título | G1: Revista o fuente | H1: País o ciudad | I1: Método | J1: Muestra | K1: Medida de demanda | L1: Cómo trata la edad | M1: Hallazgo sobre edad y demanda | N1: ¿Café de especialidad? | O1: Tema | P1: Relevancia para la pregunta | Q1: Vacío o limitación | R1: DOI o enlace | S1: Búsqueda de origen | T1: Ámbito de la evidencia | U1: Explicación que propone el estudio | V1: Fuente de la extracción | W1: Verificado por el equipo (Sí/No)
A2: A01 | B2: Académica | C2: cross-sectional study | D2: Ronald Wilde Mamani Tudela | E2: 2024 | F2: Dra. ESTIMACIÓN DE LA DISPOSICIÓN A PAGAR POR EL CAFÉ ORGÁNICO EN EL DISTRITO DE PUNO, 2022 | G2: Revista de Ciencias Agrarias | H2: Perú (Puno) | I2: Valoración contingente; logit de elección dicotómica | J2: No indicada en el resumen | K2: Disposición a pagar por taza de café orgánico de alta calidad | L2: Variable explicativa | M2: La edad es uno de los determinantes de la disposición a pagar, junto con precio, ingreso, educación y género. La educación tiene el mayor efecto marginal. Edad promedio de la muestra: 35 años. | N2: Parcial | O2: Edad y disposición a pagar | P2: Alta | Q2: Café orgánico, no de especialidad; el resumen no indica el signo del efecto de la edad. Ojo: el resumen automático de Consensus dice 'Puno, Chile'; Puno está en Perú. | R2: https://doi.org/10.53719/rca.2024.864 | S2: Does willingness to pay for specialty coffee differ by age group? | T2: Café orgánico o certificado | U2: Pendiente de lectura del texto completo | V2: Resumen
A3: A02 | B3: Académica | C3: cross-sectional study | D3: N. Saraswati, Mukson Mukson, S. Nurfadillah | E3: 2023 | F3: Analisis Kesediaan Membayar (Willingness to Pay) Konsumen Terhadap Produk Kopi Berlabel Fairtrade di Berbagai Wilayah Indonesia | G3: JSEP (Journal of Social and Agricultural Economics) | H3: Indonesia (varias regiones) | I3: Valoración contingente; regresión lineal múltiple | J3: 218 | K3: Disposición a pagar por café con sello Fairtrade | L3: Variable explicativa | M3: La edad está entre los factores que influyen conjuntamente en la disposición a pagar. Consumidor típico: mujer de 21 a 30 años. | N3: No | O3: Edad y disposición a pagar | P3: Media | Q3: Café certificado, no de especialidad; no reporta el efecto individual de la edad. | R3: https://doi.org/10.19184/jsep.v16i1.33979 | S3: Does willingness to pay for specialty coffee differ by age group? | T3: Café orgánico o certificado | U3: Pendiente de lectura del texto completo | V3: Resumen
A4: A03 | B4: Académica | C4: systematic review | D4: A. Samoggia, Bettina Riedel | E4: 2018 | F4: Coffee consumption and purchasing behavior review: Insights for further research. | G4: Appetite | H4: Internacional | I4: Revisión sistemática de literatura | J4: No aplica | K4: Consumo y compra de café | L4: Sociodemográficos como grupo de determinantes | M4: Identifica cinco grupos de determinantes: preferencias personales, atributos económicos, atributos del producto, contexto de consumo y sociodemográficos. | N4: No | O4: Marco general | P4: Alta | Q4: Consensus no exportó el resumen: hay que leer el texto completo para ver qué dice sobre la edad. | R4: https://doi.org/10.1016/j.appet.2018.07.002 | S4: Does willingness to pay for specialty coffee differ by age group? | Does consumer age influence specialty coffee consumption? | Is age associated with frequency of coffee shop visits? | T4: Café en general | U4: Pendiente de lectura del texto completo | V4: Resumen
A5: A04 | B5: Académica | C5: mixed methods study | D5: Mei-Jung (Sebrina) Wang, E. K. Opoku, Aaron Tham | E5: 2024 | F5: Exploring Gen-Z consumers’ preference for specialty coffee in the socio-cultural context of Taiwan | G5: Young Consumers | H5: Taiwán | I5: Mixto: entrevistas y pruebas de sabor; muestreo intencional | J5: No indicada en el resumen | K5: Preferencia y disposición a pagar por café de especialidad | L5: Una sola generación (Z) | M5: La generación Z percibe el café de especialidad como caro y no lo compra con regularidad. Lo asocia con salud y con consumo conspicuo en redes sociales. | N5: Sí | O5: Generaciones | P5: Alta | Q5: Una sola generación: no permite comparar por edad. | R5: https://doi.org/10.1108/yc-08-2023-1844 | S5: Does willingness to pay for specialty coffee differ by age group? | Does consumer age influence specialty coffee consumption? | T5: Café de especialidad | U5: El precio limita la compra regular; la visita funciona como consumo conspicuo en redes sociales. | V5: Resumen
A6: A05 | B6: Académica | C6: cross-sectional study | D6: Rahmawati Setiyani, Lathifah Khairani, Rajendra Agidya Putra | E6: 2026 | F6: Characteristics of Generation Z Coffee Consumers in Surakarta: A Study of Behavior and Preferences | G6: Jurnal Multidisiplin Madani | H6: Indonesia (Surakarta) | I6: Encuesta descriptiva | J6: No indicada en el resumen | K6: Comportamiento de compra y preferencias | L6: Una sola generación (Z) | M6: Consumidores de 17 a 21 años, estudiantes y de ingresos bajos. El precio es el criterio principal para elegir dónde comprar. | N6: No | O6: Generaciones | P6: Media | Q6: Una sola generación; edad confundida con ingreso y condición de estudiante. | R6: https://doi.org/10.55927/mudima.v6i8.116 | S6: Does willingness to pay for specialty coffee differ by age group? | Does the age profile of coffee shop customers vary by urban area or neighborhood type? | Does consumer age influence specialty coffee consumption? | T6: Cafeterías en general | U6: Pendiente de lectura del texto completo | V6: Resumen
A7: A12 | B7: Académica | C7: interview study | D7: Tolga Doğan, O. Atsız | E7: 2026 | F7: Coffee consumption across generations: consumer habits, motivations and constraints | G7: Journal of Hospitality and Tourism Horizons | H7: Turquía | I7: Cualitativo: 37 entrevistas semiestructuradas | J7: 37 | K7: Hábitos, motivaciones y restricciones de consumo | L7: Compara generaciones X, Y y Z | M7: Z asocia el café con placer y socialización y prefiere locales de marca. Y valora el café fuerte y recién molido. X prioriza practicidad y lugares tranquilos. El precio alto es restricción común; X es quien más reduce el consumo. | N7: No | O7: Generaciones | P7: Alta | Q7: Cualitativo: no cuantifica frecuencia ni gasto por generación. | R7: https://doi.org/10.1108/jhth-02-2026-0040 | S7: Does willingness to pay for specialty coffee differ by age group? | Does consumer age influence specialty coffee consumption? | T7: Café en general y cafeterías | U7: Cada generación da un significado distinto al café: placer y socialización (Z), significado cultural y café fuerte (Y), practicidad y lugares tranquilos (X). | V7: Resumen
A8: A13 | B8: Académica | C8: cross-sectional study | D8: P. De Pelsmacker, Liesbeth Driesen, G. Rayp | E8: 2005 | F8: Do Consumers Care about Ethics? Willingness to Pay for Fair‐Trade Coffee | G8: Journal of Consumer Affairs | H8: Bélgica | I8: Encuesta | J8: 808 | K8: Disposición a pagar por café de comercio justo | L8: Perfil de segmentos | M8: La prima promedio aceptada es 10 %. El segmento más dispuesto a pagar (11 % de la muestra) tiene entre 31 y 44 años. | N8: No | O8: Edad y disposición a pagar | P8: Media | Q8: Café de comercio justo; estudio de 2005 en Europa. | R8: https://doi.org/10.1111/j.1745-6606.2005.00019.x | S8: Does willingness to pay for specialty coffee differ by age group? | T8: Café orgánico o certificado | U8: Pendiente de lectura del texto completo | V8: Resumen
A9: A18 | B9: Académica | C9: cross-sectional study | D9: Soltomeina Park, Kyuhyeon Joo | E9: 2023 | F9: A Study on Prestige and Willingness to Pay a Premiumin the Context of Specialty Coffee Shops: Focusing on the Experience Economy | G9: Journal of MICE & Tourism Research | H9: Corea del Sur | I9: Encuesta en línea; regresión, prueba t y ANOVA | J9: 265 | K9: Disposición a pagar una prima en cafeterías de especialidad | L9: Diferencias entre grupos | M9: El prestigio de la cafetería aumenta la disposición a pagar una prima. Las dimensiones de entretenimiento y estética de la experiencia difieren por edad, educación e ingreso. | N9: Sí | O9: Edad y disposición a pagar | P9: Alta | Q9: La edad se relaciona con la experiencia, no directamente con la disposición a pagar. | R9: https://doi.org/10.35176/jmtr.23.2.10 | S9: Does willingness to pay for specialty coffee differ by age group? | T9: Café de especialidad | U9: Las dimensiones de la experiencia (educación, entretenimiento, estética, escape) elevan el prestigio de la cafetería y la disposición a pagar una prima. | V9: Resumen
A10: A21 | B10: Académica | C10: other | D10: S. Ferreira, Lukas Beuster | E10: 2019 | F10: Stellenbosch coffee society: Societal and locational preferences | G10: Urbani izziv | H10: Sudáfrica (Stellenbosch) | I10: Mixto: recorridos, encuesta y 3 entrevistas | J10: No indicada en el resumen | K10: Preferencias sociales y de localización | L10: Indirecta: estudiantes y profesionales | M10: En una ciudad universitaria, estudiantes y profesionales moldean la geografía de las cafeterías. La preferencia depende de la ubicación y del apego al lugar. | N10: Sí | O10: Zona y localización | P10: Media | Q10: No mide la edad directamente. | R10: https://doi.org/10.5379/urbani-izziv-en-2019-30-supplement-005 | S10: Does the age profile of coffee shop customers vary by urban area or neighborhood type? | T10: Café de especialidad | U10: La cafetería funciona como tercer lugar; la preferencia depende de la ubicación y del apego al lugar. | V10: Resumen
A11: A22 | B11: Académica | C11: cross-sectional study | D11: Wahyu Trianingsih, Yasin Yusup, Rahning Utomowati | E11: 2020 | F11: STUDI KERUANGAN KEDAI KOPI DAN EKONOMI KOGNITIF-BUDAYA DI KOTA SURAKARTA TAHUN 2019 (Suplemen Materi Bahan Ajar Geografi SMA Kelas X Kurikulum 2013 pada Kompetensi Dasar 3.1. Memahami Pengetahuan Dasar Geografi dan Terapannya dalam Kehidupan Sehari–Hari) | G11: GEADIDAKTIKA | H11: Indonesia (Surakarta) | I11: Cuantitativo con enfoque espacial (mapas) | J11: No indicada en el resumen | K11: Distribución de cafeterías y perfil de visitantes | L11: Descriptiva | M11: Las cafeterías se concentran en el distrito que es centro de actividad urbana. Los visitantes están en edad productiva y son de clase media-alta. | N11: No | O11: Zona y localización | P11: Media | Q11: Describe la edad sin compararla entre zonas. | R11: https://doi.org/10.20961/gea.v1i1.42080 | S11: Does the age profile of coffee shop customers vary by urban area or neighborhood type? | T11: Cafeterías en general | U11: Pendiente de lectura del texto completo | V11: Resumen
A12: A24 | B12: Académica | C12: cross-sectional study | D12: Diana Rachmatunnissa, Yosini Deliana | E12: 2020 | F12: SEGMENTASI KONSUMEN COFFEE SHOP GENERASI Z DI JATINANGOR | G12: No exportada por Consensus | H12: Indonesia (Jatinangor, zona universitaria) | I12: Encuesta con muestreo aleatorio sistemático; análisis discriminante | J12: 163 | K12: Intensidad de consumo, gasto y número de visitas | L12: Una sola generación (Z) | M12: Los clientes de cafeterías grandes y pequeñas difieren significativamente en edad, intensidad de consumo, gasto, número de visitas, distancia y tiempo de permanencia. | N12: No | O12: Zona y localización | P12: Alta | Q12: Zona universitaria: poca variación de edad. | R12: https://doi.org/10.25157/ma.v6i1.2686 | S12: Does the age profile of coffee shop customers vary by urban area or neighborhood type? | T12: Cafeterías en general | U12: Pendiente de lectura del texto completo | V12: Resumen
A13: A25 | B13: Académica | C13: cross-sectional study | D13: Feri Hendra, Y. Rohayati, Budi Sulistyo | E13: 2026 | F13: Psychographic Segmentation of Generation Z Coffee Shop Customers: An Activities, Interests, and Opinions (AIO) Approach | G13: International Journal of Applied Business and International Management | H13: Indonesia (Bandung y Yakarta) | I13: Encuesta; conglomerados K-means y ANOVA | J13: 285 | K13: Gasto por visita y frecuencia de visita | L13: Una sola generación (Z) | M13: Edad, ocupación, ingreso y gasto por visita se asocian con el segmento del cliente. El género y la frecuencia de visita no. | N13: No | O13: Generaciones | P13: Media | Q13: Una sola generación. | R13: https://doi.org/10.32535/ijabim.v11i2.4721 | S13: Does the age profile of coffee shop customers vary by urban area or neighborhood type? | T13: Cafeterías en general | U13: Pendiente de lectura del texto completo | V13: Resumen
... A43: G11 | B43: Gris | C43: Prensa | D43: Colombia.com | E43: 2026 | F43: Café de especialidad colombiano: una propuesta que hasta los más jóvenes han adaptado a sus días | G43: Colombia.com | H43: Colombia | I43: Nota de prensa | J43: No aplica | K43: No mide demanda | L43: Mención general | M43: Afirma que el crecimiento del café de especialidad lo impulsan consumidores jóvenes y urbanos. | N43: Sí | O43: Generaciones | P43: Baja | Q43: Sin cifras, sin rangos de edad y sin fuente identificable. | R43: https://www.colombia.com/gastronomia/noticias/cafe-de-especialidad-colombiano-donde-encontrarlo-565209 | S43: Búsqueda web de literatura gris | T43: Café de especialidad | U43: Pendiente de lectura del texto completo | V43: Página web o ficha

Sheet PRISMA
A1: Flujo PRISMA | B1: Académica (Consensus) | C1: Literatura gris (web) | D1: Total
A2: Identificación
A3: Registros identificados | B3: =SUM(Búsquedas!E2:E5) -> 66 | C3: =COUNTIF(Cribado!$B$2:$B$70,"Búsqueda web") -> 15 | D3: =B3+C3 -> 81
A4: Duplicados eliminados | B4: =B3-COUNTIF(Cribado!$B$2:$B$70,"Consensus") -> 12 | C4: =COUNTIFS(Cribado!$B$2:$B$70,"Búsqueda web",Cribado!$I$2:$I$70,"Duplica*") -> 1 | D4: =B4+C4 -> 13
A5: Cribado
A6: Registros cribados por título y resumen | B6: =B3-B4 -> 54 | C6: =C3-C4 -> 14 | D6: =B6+C6 -> 68
A7: Registros excluidos | B7: =COUNTIFS(Cribado!$B$2:$B$70,"Consensus",Cribado!$H$2:$H$70,"Excluido") -> 22 | C7: =COUNTIFS(Cribado!$B$2:$B$70,"Búsqueda web",Cribado!$H$2:$H$70,"Excluido")-C4 -> 4 | D7: =B7+C7 -> 26
A8: Inclusión
A9: Documentos incluidos | B9: =COUNTIFS(Cribado!$B$2:$B$70,"Consensus",Cribado!$H$2:$H$70,"Incluido") -> 32 | C9: =COUNTIFS(Cribado!$B$2:$B$70,"Búsqueda web",Cribado!$H$2:$H$70,"Incluido") -> 10 | D9: =B9+C9 -> 42
A10: Comprobación (debe ser 0) | B10: =B6-B7-B9 -> 0 | C10: =C6-C7-C9 -> 0 | D10: =D6-D7-D9 -> 0
A12: Motivos de exclusión | B12: Registros
A13: Describe la edad de la muestra sin relacionarla con la demanda | B13: =COUNTIF(Cribado!$I$2:$I$70,A13) -> 2
A14: Enfoque en salud, sin medida de demanda | B14: =COUNTIF(Cribado!$I$2:$I$70,A14) -> 3
A15: Fuera de tema: no estudia demanda de café | B15: =COUNTIF(Cribado!$I$2:$I$70,A15) -> 2
A16: Integridad dudosa: resumen casi idéntico al de Yang et al. (2012) | B16: =COUNTIF(Cribado!$I$2:$I$70,A16) -> 1
A17: La edad se vincula a percepción de salud, no a demanda | B17: =COUNTIF(Cribado!$I$2:$I$70,A17) -> 1
A18: No reporta resultados por edad o generación en el resumen | B18: =COUNTIF(Cribado!$I$2:$I$70,A18) -> 9
A19: Preferencia sensorial, no demanda | B19: =COUNTIF(Cribado!$I$2:$I$70,A19) -> 1
A20: Una sola cohorte, sin medida de demanda ni comparación por edad | B20: =COUNTIF(Cribado!$I$2:$I$70,A20) -> 3
A21: Sin datos de consumidores ni de zonas | B21: =COUNTIF(Cribado!$I$2:$I$70,A21) -> 1
A22: Sin datos de consumidores por edad; cifras de 2014 sin fuente | B22: =COUNTIF(Cribado!$I$2:$I$70,A22) -> 1
A23: Sin datos de edad; contenido promocional de una marca | B23: =COUNTIF(Cribado!$I$2:$I$70,A23) -> 1
A24: Sin datos por edad ni sobre cafeterías | B24: =COUNTIF(Cribado!$I$2:$I$70,A24) -> 1
A25: Total excluidos | B25: =SUM(B13:B24) -> 26
A27: Criterios y limitaciones
A28: Inclusión 1: estudia consumo, compra, visita a cafeterías o disposición a pagar por café, o la localización de cafeterías frente a la demografía de la zona.
A29: Inclusión 2: reporta un resultado por edad o generación, caracteriza con medidas de demanda a una cohorte definida, o describe el consumo de café de especialidad de una generación.
A30: Literatura gris: se incluye si trata el consumo de café o las cafeterías de especialidad en Colombia o Bogotá y aporta datos de consumidores o de zonas.
A31: El cribado se hizo sobre título y resumen. Falta la lectura de texto completo de los documentos incluidos (fase de elegibilidad de PRISMA).
A32: Consensus devuelve los resultados más relevantes de cada pregunta, no todos los existentes: la búsqueda no es exhaustiva.
A33: La literatura gris la buscó y abrió Claude el 2026-10-07 mediante búsqueda web; el equipo debe verificarla y puede ampliarla.
A34: Los resúmenes automáticos de Consensus tienen errores (por ejemplo, ubican Puno en Chile). Los hallazgos de la hoja Documentos se tomaron del resumen original de cada artículo.
A35: Entrega 2b: se leyó el texto completo de 4 estudios (A37, A39, A45, A53). La columna amarilla 'Verificado por el equipo' de la hoja Documentos queda para que el equipo confirme cada fuente original.

Sheet Cribado
A1: ID | B1: Origen | C1: Autores | D1: Año | E1: Título | F1: Búsquedas en que apareció | G1: Búsqueda de origen | H1: Decisión | I1: Motivo de exclusión
A2: A01 | B2: Consensus | C2: Ronald Wilde Mamani Tudela | D2: 2024 | E2: Dra. ESTIMACIÓN DE LA DISPOSICIÓN A PAGAR POR EL CAFÉ ORGÁNICO EN EL DISTRITO DE PUNO, 2022 | F2: 1 | G2: Does willingness to pay for specialty coffee differ by age group? | H2: Incluido
A3: A02 | B3: Consensus | C3: N. Saraswati, Mukson Mukson, S. Nurfadillah | D3: 2023 | E3: Analisis Kesediaan Membayar (Willingness to Pay) Konsumen Terhadap Produk Kopi Berlabel Fairtrade di Berbagai Wilayah Indonesia | F3: 1 | G3: Does willingness to pay for specialty coffee differ by age group? | H3: Incluido
A4: A03 | B4: Consensus | C4: A. Samoggia, Bettina Riedel | D4: 2018 | E4: Coffee consumption and purchasing behavior review: Insights for further research. | F4: 3 | G4: Does willingness to pay for specialty coffee differ by age group? | Does consumer age influence specialty coffee consumption? | Is age associated with frequency of coffee shop visits? | H4: Incluido
A5: A04 | B5: Consensus | C5: Mei-Jung (Sebrina) Wang, E. K. Opoku, Aaron Tham | D5: 2024 | E5: Exploring Gen-Z consumers’ preference for specialty coffee in the socio-cultural context of Taiwan | F5: 2 | G5: Does willingness to pay for specialty coffee differ by age group? | Does consumer age influence specialty coffee consumption? | H5: Incluido
A6: A05 | B6: Consensus | C6: Rahmawati Setiyani, Lathifah Khairani, Rajendra Agidya Putra | D6: 2026 | E6: Characteristics of Generation Z Coffee Consumers in Surakarta: A Study of Behavior and Preferences | F6: 3 | G6: Does willingness to pay for specialty coffee differ by age group? | Does the age profile of coffee shop customers vary by urban area or neighborhood type? | Does consumer age influence specialty coffee consumption? | H6: Incluido
A7: A06 | B7: Consensus | C7: Ayu Wulandari Priyambodoi, A. Kholil | D7: 2021 | E7: Willingness To Pay Fair Trade Coffee In Malang East Java Indonesia | F7: 1 | G7: Does willingness to pay for specialty coffee differ by age group? | H7: Excluido | I7: Integridad dudosa: resumen casi idéntico al de Yang et al. (2012)
A8: A07 | B8: Consensus | C8: A. Samoggia, Bettina Riedel | D8: 2019 | E8: Consumers’ Perceptions of Coffee Health Benefits and Motives for Coffee Consumption and Purchasing | F8: 1 | G8: Does willingness to pay for specialty coffee differ by age group? | H8: Excluido | I8: La edad se vincula a percepción de salud, no a demanda
A9: A08 | B9: Consensus | C9: Chun-Chu Liu, Chu-Wei Chen, Han-Shen Chen | D9: 2019 | E9: Measuring Consumer Preferences and Willingness to Pay for Coffee Certification Labels in Taiwan | F9: 1 | G9: Does willingness to pay for specialty coffee differ by age group? | H9: Excluido | I9: No reporta resultados por edad o generación en el resumen
A10: A09 | B10: Consensus | C10: Veenarat Ut-tha, Pai-Po Lee, R. Chung | D10: 2021 | E10: Willingness to Pay for Sustainable Coffee: A Case of Thai Consumers | F10: 1 | G10: Does willingness to pay for specialty coffee differ by age group? | H10: Excluido | I10: No reporta resultados por edad o generación en el resumen
A11: A10 | B11: Consensus | C11: B. Kurek, Ireneusz Górowski | D11: 2025 | E11: Willingness to Pay for Green Energy: Exploring Generation Z Perspectives | F11: 1 | G11: Does willingness to pay for specialty coffee differ by age group? | H11: Excluido | I11: Fuera de tema: no estudia demanda de café
A12: A11 | B12: Consensus | C12: Andika Wicaksono Putro, Å. Rinnan, M. B. Frøst | D12: 2025 | E12: Indonesians would like their coffee produced organically! – Preferences for iced coffee analysed with a discrete choice experiment | F12: 1 | G12: Does willingness to pay for specialty coffee differ by age group? | H12: Excluido | I12: No reporta resultados por edad o generación en el resumen
A13: A12 | B13: Consensus | C13: Tolga Doğan, O. Atsız | D13: 2026 | E13: Coffee consumption across generations: consumer habits, motivations and constraints | F13: 2 | G13: Does willingness to pay for specialty coffee differ by age group? | Does consumer age influence specialty coffee consumption? | H13: Incluido
A14: A13 | B14: Consensus | C14: P. De Pelsmacker, Liesbeth Driesen, G. Rayp | D14: 2005 | E14: Do Consumers Care about Ethics? Willingness to Pay for Fair‐Trade Coffee | F14: 1 | G14: Does willingness to pay for specialty coffee differ by age group? | H14: Incluido
A15: A14 | B15: Consensus | C15: Y. Rahayu, U. Sumarwan, Y. Asnawi | D15: 2023 | E15: Perception Analysis of Purchasing Attitude And Willingness To Pay For Coffee and Non-Coffee Beverage Products | F15: 1 | G15: Does willingness to pay for specialty coffee differ by age group? | H15: Excluido | I15: No reporta resultados por edad o generación en el resumen
A16: A15 | B16: Consensus | C16: Nizam Abdu, Judith Mutuku | D16: 2021 | E16: Willingness to pay for socially responsible products: A meta−analysis of coffee ecolabelling | F16: 1 | G16: Does willingness to pay for specialty coffee differ by age group? | H16: Excluido | I16: No reporta resultados por edad o generación en el resumen
A17: A16 | B17: Consensus | C17: K. Fuller, Carola Grebitus | D17: 2023 | E17: Consumers' preferences and willingness to pay for coffee sustainability labels | F17: 1 | G17: Does willingness to pay for specialty coffee differ by age group? | H17: Excluido | I17: No reporta resultados por edad o generación en el resumen
A18: A17 | B18: Consensus | C18: D. Ufer, Wen Lin, David L. Ortega | D18: 2019 | E18: Personality traits and preferences for specialty coffee: Results from a coffee shop field experiment. | F18: 1 | G18: Does willingness to pay for specialty coffee differ by age group? | H18: Excluido | I18: No reporta resultados por edad o generación en el resumen
A19: A18 | B19: Consensus | C19: Soltomeina Park, Kyuhyeon Joo | D19: 2023 | E19: A Study on Prestige and Willingness to Pay a Premiumin the Context of Specialty Coffee Shops: Focusing on the Experience Economy | F19: 1 | G19: Does willingness to pay for specialty coffee differ by age group? | H19: Incluido
A20: A19 | B20: Consensus | C20: Sutan Mhd Amin Jamal, Edy Prasetyo | D20: 2020 | E20: KESEDIAAN MEMBAYAR (WILLINGNESS TO PAY) TERHADAP PRODUK COFFEE LATTE DI KOTA SEMARANG | F20: 1 | G20: Does willingness to pay for specialty coffee differ by age group? | H20: Excluido | I20: No reporta resultados por edad o generación en el resumen
A21: A20 | B21: Consensus | C21: Shang-Ho Yang, Wu-Yang Hu, Malvern Mupandawana, Yun Liu | D21: 2012 | E21: Consumer Willingness to Pay for Fair Trade Coffee: A Chinese Case Study | F21: 1 | G21: Does willingness to pay for specialty coffee differ by age group? | H21: Excluido | I21: No reporta resultados por edad o generación en el resumen
A22: A21 | B22: Consensus | C22: S. Ferreira, Lukas Beuster | D22: 2019 | E22: Stellenbosch coffee society: Societal and locational preferences | F22: 1 | G22: Does the age profile of coffee shop customers vary by urban area or neighborhood type? | H22: Incluido
A23: A22 | B23: Consensus | C23: Wahyu Trianingsih, Yasin Yusup, Rahning Utomowati | D23: 2020 | E23: STUDI KERUANGAN KEDAI KOPI DAN EKONOMI KOGNITIF-BUDAYA DI KOTA SURAKARTA TAHUN 2019 (Suplemen Materi Bahan Ajar Geografi SMA Kelas X Kurikulum 2013 pada Kompetensi Dasar 3.1. Memahami Pengetahuan Dasar Geografi dan Terapannya dalam Kehidupan Sehari–Hari) | F23: 1 | G23: Does the age profile of coffee shop customers vary by urban area or neighborhood type? | H23: Incluido
A24: A23 | B24: Consensus | C24: H. Yi, Shu-Tian Ng, Cheng-Mun Chang, C. Low, C. Tan | D24: 2022 | E24: Effects of neighborhood features on healthy aging in place: the composition and context of urban parks and traditional local coffeeshops in Singapore | F24: 1 | G24: Does the age profile of coffee shop customers vary by urban area or neighborhood type? | H24: Excluido | I24: Enfoque en salud, sin medida de demanda
A25: A24 | B25: Consensus | C25: Diana Rachmatunnissa, Yosini Deliana | D25: 2020 | E25: SEGMENTASI KONSUMEN COFFEE SHOP GENERASI Z DI JATINANGOR | F25: 1 | G25: Does the age profile of coffee shop customers vary by urban area or neighborhood type? | H25: Incluido
A26: A25 | B26: Consensus | C26: Feri Hendra, Y. Rohayati, Budi Sulistyo | D26: 2026 | E26: Psychographic Segmentation of Generation Z Coffee Shop Customers: An Activities, Interests, and Opinions (AIO) Approach | F26: 1 | G26: Does the age profile of coffee shop customers vary by urban area or neighborhood type? | H26: Incluido
A27: A26 | B27: Consensus | C27: J. Finlay, Michael H. Esposito, Sandra Tang, Iris N. Gomez-Lopez, Dominique L Sylvers, S. Judd, Philippa J. Clarke | D27: 2020 | E27: Fast-food for thought: Retail food environments as resources for cognitive health and wellbeing among aging Americans? | F27: 2 | G27: Does the age profile of coffee shop customers vary by urban area or neighborhood type? | Is age associated with frequency of coffee shop visits? | H27: Excluido | I27: Enfoque en salud, sin medida de demanda
A28: A27 | B28: Consensus | C28: Novi Catur Muspita, Ainun Najib | D28: 2021 | E28: THE PHENOMENA OF BEHAVIOR HANDLING IN COFFEE SHOPS AS A PUBLIC SPACE: STUDY ON CONSUMERS OF DREAM COFFE KOPI STORES In BLITAR CITY | F28: 1 | G28: Does the age profile of coffee shop customers vary by urban area or neighborhood type? | H28: Excluido | I28: Describe la edad de la muestra sin relacionarla con la demanda
A29: A28 | B29: Consensus | C29: H. Maulina, M. Novita, M. Rahmany | D29: 2025 | E29: Analysis of coffee truck consumer segmentation in Banda Aceh city | F29: 1 | G29: Does the age profile of coffee shop customers vary by urban area or neighborhood type? | H29: Incluido
A30: A29 | B30: Consensus | C30: Ayşe Buket Önem, K. Arslanlı | D30: 2024 | E30: The evolving landscape of Istanbul's coffee shops: Navigating disruption in a changing urban environment | F30: 1 | G30: Does the age profile of coffee shop customers vary by urban area or neighborhood type? | H30: Incluido
A31: A30 | B31: Consensus | C31: E. Loftfield, N. Freedman, K. Dodd, E. Vogtmann, Qian Xiao, R. Sinha, B. Graubard | D31: 2016 | E31: Coffee Drinking Is Widespread in the United States, but Usual Intake Varies by Key Demographic and Lifestyle Factors. | F31: 2 | G31: Does consumer age influence specialty coffee consumption? | Is age associated with frequency of coffee shop visits? | H31: Incluido
A32: A31 | B32: Consensus | C32: C. Rehm, Joseph C. Ratliff, Claudia S. Riedt, A. Drewnowski | D32: 2020 | E32: Coffee Consumption among Adults in the United States by Demographic Variables and Purchase Location: Analyses of NHANES 2011–2016 Data | F32: 2 | G32: Does consumer age influence specialty coffee consumption? | Is age associated with frequency of coffee shop visits? | H32: Incluido
A33: A32 | B33: Consensus | C33: Dylan Yeon Joon Cho | D33: 2026 | E33: Age Patterns, Cohort-proxy Trends, and Scenario-based U.S. Coffee Participation through 2040 | F33: 2 | G33: Does consumer age influence specialty coffee consumption? | Is age associated with frequency of coffee shop visits? | H33: Incluido
A34: A33 | B34: Consensus | C34: A. Utama, U. Sumarwan, A. Suroso, M. Najib | D34: 2021 | E34: Roles of Regulation and Lifestyle on Indonesian Coffee Consumption Behavior Across Generations | F34: 1 | G34: Does consumer age influence specialty coffee consumption? | H34: Incluido
A35: A34 | B35: Consensus | C35: Xinyue Xu, A. Ng | D35: 2022 | E35: Cultivation of new taste: taste makers and new forms of distinction in China’s Coffee Culture | F35: 1 | G35: Does consumer age influence specialty coffee consumption? | H35: Incluido
A36: A35 | B36: Consensus | C36: D. Ismoyowati, F. Wijayanti | D36: 2023 | E36: Millennials' Consumer Behavior in the Coffee Agroindustry: The Effect of Consumer Attitudes on Purchasing Decisions | F36: 1 | G36: Does consumer age influence specialty coffee consumption? | H36: Excluido | I36: Una sola cohorte, sin medida de demanda ni comparación por edad
A37: A36 | B37: Consensus | C37: Alessandra Gaspar Sousa, L. M. M. Machado, E. F. D. Da Silva, Teresa Helena Macedo da Costa | D37: 2016 | E37: Personal characteristics of coffee consumers and non-consumers, reasons and preferences for foods eaten with coffee among adults from the Federal District, Brazil | F37: 1 | G37: Does consumer age influence specialty coffee consumption? | H37: Incluido
A38: A37 | B38: Consensus | C38: J. Drábeková, Adriána Spiššáková | D38: 2023 | E38: Consumers, cafes, baristas, and statistical analysis of their interactions | F38: 2 | G38: Does consumer age influence specialty coffee consumption? | Is age associated with frequency of coffee shop visits? | H38: Incluido
A39: A38 | B39: Consensus | C39: Ave Agatha Simamora, Hanry Imanuel, Firman Rahmadi, Yayasan Pusat, Studi Pembangunan, Manusia Dan, Alam Sekitar | D39: 2025 | E39: Consumer Preferences for Gayo Coffee and Cappuccino Among Agribusiness Students at Universitas Medan Area | F39: 1 | G39: Does consumer age influence specialty coffee consumption? | H39: Excluido | I39: Una sola cohorte, sin medida de demanda ni comparación por edad
A40: A39 | B40: Consensus | C40: Y. N. Muflikh, Depicha Zambustya Zamborita, Al-May Abbyan Izzy Burhani | D40: 2024 | E40: Purchasing Decisions and Consumer Preferences of Millennials and Zoomers at Coffee Shops | F40: 1 | G40: Does consumer age influence specialty coffee consumption? | H40: Incluido
...

Sheet Búsquedas
A1: ID | B1: Herramienta | C1: Pregunta o cadena de búsqueda | D1: Fecha | E1: Registros exportados | F1: Nota
A2: B1 | B2: Consensus | C2: Does willingness to pay for specialty coffee differ by age group? | D2: 2026-10-07 | E2: 20 | F2: Exportación CSV enviada por el equipo
A3: B2 | B3: Consensus | C3: Does the age profile of coffee shop customers vary by urban area or neighborhood type? | D3: 2026-10-07 | E3: 10 | F3: Exportación CSV enviada por el equipo
A4: B3 | B4: Consensus | C4: Does consumer age influence specialty coffee consumption? | D4: 2026-10-07 | E4: 18 | F4: Exportación CSV enviada por el equipo
A5: B4 | B5: Consensus | C5: Is age associated with frequency of coffee shop visits? | D5: 2026-10-07 | E5: 18 | F5: Exportación CSV enviada por el equipo
A6: B5 | B6: Búsqueda web | C6: café de especialidad Bogotá consumidores jóvenes tiendas de café crecimiento | D6: 2026-10-07 | F6: Se abrieron y evaluaron 15 documentos en total entre las seis búsquedas web
A7: B6 | B7: Búsqueda web | C7: tesis perfil del consumidor café especial Bogotá edad repositorio universidad | D7: 2026-10-07 | F7: Se abrieron y evaluaron 15 documentos en total entre las seis búsquedas web
A8: B7 | B8: Búsqueda web | C8: Federación Nacional de Cafeteros consumo interno café Colombia estudio consumidores edad jóvenes | D8: 2026-10-07 | F8: Se abrieron y evaluaron 15 documentos en total entre las seis búsquedas web
A9: B8 | B9: Búsqueda web | C9: Cámara de Comercio de Bogotá cafés especiales Bogotá estudio tiendas de café Secretaría Desarrollo Económico | D9: 2026-10-07 | F9: Se abrieron y evaluaron 15 documentos en total entre las seis búsquedas web
A10: B9 | B10: Búsqueda web | C10: "café de especialidad" OR "cafés especiales" Bogotá consumidor caracterización encuesta edad trabajo de grado Chapinero | D10: 2026-10-07 | F10: Se abrieron y evaluaron 15 documentos en total entre las seis búsquedas web
A11: B10 | B11: Búsqueda web | C11: número de tiendas de café de especialidad en Bogotá localidades Chapinero Usaquén cifras 2025 | D11: 2026-10-07 | F11: Se abrieron y evaluaron 15 documentos en total entre las seis búsquedas web
